Workbook
Name Slicer_Garage_Name: #N/A
Name Slicer_Vehicle_Type: #N/A
Name Slicer_VOR_SLA_Breached?: #N/A

Sheet Fleet_Data
A1: Vehicle_ID | B1: Vehicle_Type | C1: Make_Model | D1: Defect_Reported_DateTime | E1: Garage_Booked_DateTime | F1: Garage_In_Date | G1: Garage_Out_Date | H1: Actual_Repair_Start_Date | I1: Estimated_Completion_Date | J1: Primary_Delay_Reason | K1: MOT_Linked | L1: Repeated_Defect_Last_30_Days | M1: Garage_Name | N1: Column1
A2: VH1000 | B2: Specialised | C2: Ford Transit | D2: 46035.562 | E2: 46036.258 | F2: 46038.258 | G2: 46040.258 | H2: 46038.354 | I2: 46039 | J2: None (On Time) | K2: Yes | L2: No | M2: Joey Special Auto Centre
A3: VH1001 | B3: Standard | C3: Vauxhall Vivaro | D3: 46102.552 | E3: 46104.765 | F3: 46104.931 | G3: 46108.531 | H3: 46105.098 | I3: 46108 | J3: Recovery Delivery Failure | K3: No | L3: No | M3: Geller Repair Shop
A4: VH1002 | B4: Standard | C4: Mercedes Atego | D4: 46081.552 | E4: 46083.415 | F4: 46083.748 | G4: 46088.948 | H4: 46083.915 | I4: 46087 | J4: Garage Capacity / Ramp Delay | K4: No | L4: Yes | M4: Central Perk Repairs
A5: VH1003 | B5: Specialised | C5: Iveco Daily | D5: 46082.604 | E5: 46084.317 | F5: 46085.817 | G5: 46089.817 | H5: 46085.983 | I5: 46088 | J5: Garage Capacity / Ramp Delay | K5: No | L5: No | M5: 15 Yemen Rd Garage
A6: VH1004 | B6: Specialised | C6: Iveco Daily | D6: 46031.479 | E6: 46032.783 | F6: 46034.783 | G6: 46041.283 | H6: 46035.354 | I6: 46039 | J6: Awaiting Client Authorization | K6: No | L6: No | M6: Joey Special Auto Centre
A7: VH1005 | B7: Standard | C7: Vauxhall Vivaro | D7: 46097.615 | E7: 46097.948 | F7: 46098.115 | G7: 46107.515 | H7: 46098.115 | I7: 46106 | J7: Parts on Backorder | K7: Yes | L7: Yes | M7: Princess Consuela Auto Centre
A8: VH1006 | B8: Standard | C8: Vauxhall Vivaro | D8: 46077.708 | E8: 46079.075 | F8: 46080.075 | G8: 46086.075 | H8: 46080.396 | I8: 46085 | J8: Incorrect Defect Diagnosis | K8: No | L8: No | M8: PIVOT Garage Repairs
A9: VH1007 | B9: Standard | C9: Vauxhall Vivaro | D9: 46136.688 | E9: 46139.075 | F9: 46139.408 | G9: 46141.808 | H9: 46139.408 | I9: 46140 | J9: None (On Time) | K9: No | L9: No | M9: Joey Special Auto Centre
A10: VH1008 | B10: Standard | C10: Vauxhall Movano | D10: 46120.417 | E10: 46123.238 | F10: 46125.238 | G10: 46128.238 | H10: 46125.404 | I10: 46128 | J10: None (On Time) | K10: Yes | L10: No | M10: Central Perk Repairs
A11: VH1009 | B11: Standard | C11: Ford Transit | D11: 46099.573 | E11: 46103.956 | F11: 46104.29 | G11: 46109.09 | H11: 46107.417 | I11: 46110 | J11: Garage Capacity / Ramp Delay | K11: No | L11: No | M11: Dr Drake Ramoray Autos
A12: VH1010 | B12: Standard | C12: Ford Transit | D12: 46120.677 | E12: 46123.69 | F12: 46125.19 | G12: 46130.99 | H12: 46125.385 | I12: 46130 | J12: Parts on Backorder | K12: No | L12: No | M12: Central Perk Repairs
A13: VH1011 | B13: Specialised | C13: Mercedes Atego | D13: 46114.531 | E13: 46116.252 | F13: 46117.252 | G13: 46121.352 | H13: 46117.252 | I13: 46119 | J13: Parts on Backorder | K13: No | L13: No | M13: 15 Yemen Rd Garage
A14: VH1012 | B14: Standard | C14: Vauxhall Movano | D14: 46093.469 | E14: 46097.198 | F14: 46097.198 | G14: 46101.498 | H14: 46097.365 | I14: 46100 | J14: Garage Capacity / Ramp Delay | L14: No | M14: Mississippilessly Repairs
A15: VH1013 | B15: Specialised | C15: Mercedes Atego | D15: 46050.677 | E15: 46051.765 | F15: 46053.265 | G15: 46053.765 | H15: 46053.265 | I15: 46053 | J15: None (On Time) | K15: No | L15: No | M15: PIVOT Garage Repairs
A16: VH1014 | B16: Specialised | C16: Iveco Daily | D16: 46077.615 | E16: 46078.902 | F16: 46080.902 | G16: 46084.602 | H16: 46080.902 | I16: 46082 | J16: Parts on Backorder | K16: Yes | L16: No | M16: PIVOT Garage Repairs
A17: VH1015 | B17: Standard | C17: Iveco Daily | D17: 46047.49 | E17: 46050.152 | F17: 46051.152 | G17: 46056.352 | H17: 46051.319 | I17: 46056 | J17: Garage Capacity / Ramp Delay | K17: No | L17: No | M17: Central Perk Repairs
A18: VH1016 | B18: Standard | C18: Ford Transit | D18: 46029.667 | E18: 46034.012 | F18: 46034.179 | G18: 46037.479 | H18: 46036.354 | I18: 46035 | J18: None (On Time) | K18: No | L18: Yes | M18: 15 Yemen Rd Garage
A19: VH1017 | B19: Specialised | C19: Iveco Daily | D19: 46072.531 | E19: 46073.619 | F19: 46075.619 | G19: 46082.819 | J19: Unknown | K19: No | L19: No | M19: Joey Special Auto Centre
A20: VH1018 | B20: Standard | C20: Iveco Daily | D20: 46030.708 | E20: 46032.996 | F20: 46034.496 | G20: 46037.996 | H20: 46036.438 | I20: 46036 | J20: None (On Time) | K20: No | L20: No | M20: Central Perk Repairs
A21: VH1019 | B21: Specialised | C21: Vauxhall Movano | D21: 46031.708 | E21: 46032.8 | F21: 46033 | G21: 46035.7 | H21: 46033.167 | I21: 46034 | J21: None (On Time) | K21: No | L21: No | M21: PIVOT Garage Repairs
A22: VH1020 | B22: Specialised | C22: Mercedes Atego | D22: 46095.688 | E22: 46097.117 | F22: 46099.117 | G22: 46102.817 | H22: 46100.438 | I22: 46101 | J22: Garage Capacity / Ramp Delay | K22: No | L22: Yes | M22: Dr Drake Ramoray Autos
A23: VH1021 | B23: Standard | C23: Mercedes Atego | D23: 46141.375 | E23: 46141.708 | F23: 46141.708 | G23: 46151.808 | H23: 46142.375 | I23: 46151 | J23: Incorrect Defect Diagnosis | K23: No | L23: No | M23: Mississippilessly Repairs
A24: VH1022 | C24: Mercedes Atego | D24: 46059.448 | E24: 46062.456 | F24: 46063.956 | G24: 46065.456 | H24: 46064.354 | I24: 46064 | J24: None (On Time) | K24: No | L24: No | M24: Central Perk Repairs
A25: VH1023 | B25: Standard | C25: Mercedes Atego | D25: 46142.385 | E25: 46144.502 | F25: 46146.502 | G25: 46154.902 | H25: 46146.502 | I25: 46153 | J25: Recovery Delivery Failure | K25: No | L25: No | M25: Mississippilessly Repairs
A26: VH1024 | B26: Standard | C26: Vauxhall Vivaro | D26: 46104.531 | E26: 46106.81 | F26: 46106.81 | G26: 46115.41 | H26: 46106.977 | I26: 46114 | J26: Parts on Backorder | K26: No | L26: No | M26: Princess Consuela Auto Centre
A27: VH1025 | B27: Specialised | C27: Vauxhall Vivaro | D27: 46043.656 | E27: 46044.706 | F27: 46046.706 | G27: 46050.506 | H27: 46046.706 | I27: 46048 | J27: Garage Capacity / Ramp Delay | K27: No | L27: No | M27: Princess Consuela Auto Centre
A28: VH1026 | B28: Standard | C28: Renault Sprinter | D28: 46039.354 | E28: 46040.238 | F28: 46040.238 | G28: 46047.938 | H28: 46041.375 | I28: 46048 | J28: Parts on Backorder | K28: No | L28: No | M28: Central Perk Repairs
A29: VH1027 | B29: Specialised | C29: Vauxhall Vivaro | D29: 46118.427 | E29: 46120.273 | F29: 46120.44 | G29: 46120.94 | H29: 46120.44 | I29: 46121 | J29: None (On Time) | L29: No | M29: Geller Repair Shop
A30: VH1028 | B30: Specialised | C30: Vauxhall Movano | D30: 46126.479 | E30: 46127.983 | F30: 46128.983 | G30: 46135.783 | H30: 46128.983 | I30: 46133 | J30: Incorrect Defect Diagnosis | K30: No | L30: No | M30: Dr Drake Ramoray Autos
A31: VH1029 | B31: Specialised | C31: Iveco Daily | D31: 46124.469 | E31: 46125.906 | F31: 46126.24 | G31: 46130.64 | H31: 46126.479 | I31: 46128 | J31: Parts on Backorder | K31: Yes | L31: No | M31: Central Perk Repairs
A32: VH1030 | B32: Standard | C32: Renault Sprinter | D32: 46109.688 | E32: 46112.4 | F32: 46112.733 | G32: 46116.533 | H32: 46112.9 | I32: 46116 | J32: Awaiting Client Authorization | K32: No | L32: No | M32: Geller Repair Shop
A33: VH1031 | B33: Specialised | C33: Renault Sprinter | D33: 46063.583 | E33: 46065.771 | F33: 46067.271 | G33: 46071.671 | H33: 46067.396 | I33: 46070 | J33: Awaiting Client Authorization | K33: No | L33: No | M33: Mississippilessly Repairs
A34: VH1032 | B34: Standard | C34: Mercedes Atego | D34: 46078.396 | E34: 46080.946 | F34: 46082.446 | G34: 46085.146 | H34: 46082.446 | I34: 46085 | J34: None (On Time) | K34: No | M34: Geller Repair Shop
A35: VH1033 | B35: Standard | C35: Vauxhall Vivaro | D35: 46060.677 | E35: 46064.606 | F35: 46064.773 | G35: 46065.273 | H35: 46065.273 | I35: 46065 | J35: None (On Time) | K35: No | L35: No | M35: Central Perk Repairs
A36: VH1034 | B36: Standard | C36: Ford Transit | D36: 46061.51 | E36: 46064.844 | F36: 46065.844 | G36: 46070.644 | H36: 46066.01 | I36: 46068 | J36: Awaiting Client Authorization | K36: No | L36: No | M36: Princess Consuela Auto Centre
A37: VH1035 | B37: Specialised | C37: Ford Transit | D37: 46088.729 | E37: 46089.467 | F37: 46089.467 | G37: 46095.067 | H37: 46089.458 | I37: 46094 | J37: Incorrect Defect Diagnosis | K37: No | L37: Yes | M37: Mississippilessly Repairs
A38: VH1036 | B38: Standard | C38: Renault Sprinter | D38: 46101.406 | E38: 46102.306 | F38: 46103.306 | G38: 46109.506 | H38: 46103.306 | I38: 46108 | J38: Parts on Backorder | K38: No | L38: No | M38: 15 Yemen Rd Garage
A39: VH1037 | B39: Standard | C39: Ford Transit | D39: 46122.594 | E39: 46124.098 | F39: 46124.265 | G39: 46129.465 | H39: 46126.354 | I39: 46130 | J39: Recovery Delivery Failure | K39: No | L39: No | M39: Princess Consuela Auto Centre
A40: VH1038 | B40: Standard | C40: Renault Sprinter | D40: 46108.688 | E40: 46109.646 | F40: 46110.646 | G40: 46112.446 | H40: 46110.812 | I40: 46111 | J40: None (On Time) | K40: No | L40: No | M40: Dr Drake Ramoray Autos
...

Sheet Cleaned_Data
A1: Vehicle_ID | B1: Vehicle_Type | C1: Make_Model | D1: Defect_Reported_DateTime | E1: Garage_Booked_DateTime | F1: Garage_In_Date | G1: Garage_Out_Date | H1: Actual_Repair_Start_Date | I1: Estimated_Completion_Date | J1: Primary_Delay_Reason | K1: Garage_Name | L1: Hours_To_Book | M1: Booking_SLA_Breached? | N1: Total_VOR_Days | O1: VOR_SLA_Breached? | P1: Specialist_Priority_Effectiveness | Q1: Hours_To_Start_Repair | R1: MOT_Linked (XLOOKUP) | S1: Column1 | T1: =COUNTIF(N2:N101,"<3.5") -> 36
A2: VH1000 | B2: Specialised | C2: Ford Transit | D2: 46035.562 | E2: 46036.258 | F2: 46038.258 | G2: 46040.258 | H2: 46038.354 | I2: 46039 | J2: None (On Time) | K2: Joey Special Auto Centre | L2: =(Table8[[#This Row],[Garage_Booked_DateTime]] - Table8[[#This Row],[Defect_Reported_DateTime]])*24 -> 16.7 | M2: =IF(Table8[[#This Row],[Vehicle_Type]]<>"Specialised", "Not Applicable", IF(Table8[[#This Row],[Hours_To_Book]]>48, "Yes", "No")) -> No | N2: =(Table8[[#This Row],[Garage_Out_Date]]-Table8[[#This Row],[Garage_In_Date]]) -> 2 | O2: =IF(Table8[[#This Row],[Total_VOR_Days]] >3.5, "Yes", "No") -> No | P2: =IF(Table8[[#This Row],[Vehicle_Type]] <> "Specialised", "Not Applicable", IF(AND(Table8[[#This Row],[Hours_To_Book]] <=48, Table8[[#This Row],[Total_VOR_Days]] >3.5), "Ineffective", "Effective")) -> Effective | Q2: =IF(OR(Table8[[#This Row],[Garage_In_Date]]="",Table8[[#This Row],[Actual_Repair_Start_Date]]=""),"N/A",(Table8[[#This Row],[Actual_Repair_Start_Date]]-Table8[[#This Row],[Garage_In_Date]])*24) -> 2.3 | R2: =_xlfn.XLOOKUP(Table8[[#This Row],[Vehicle_ID]],Table5[Vehicle_ID],Table5[MOT_Linked],"Not Found") -> Yes
A3: VH1001 | B3: Standard | C3: Vauxhall Vivaro | D3: 46102.552 | E3: 46104.765 | F3: 46104.931 | G3: 46108.531 | H3: 46105.098 | I3: 46108 | J3: Unknown / Insufficient Data | K3: Geller Repair Shop | L3: =(Table8[[#This Row],[Garage_Booked_DateTime]] - Table8[[#This Row],[Defect_Reported_DateTime]])*24 -> 53.1 | M3: =IF(Table8[[#This Row],[Vehicle_Type]]<>"Specialised", "Not Applicable", IF(Table8[[#This Row],[Hours_To_Book]]>48, "Yes", "No")) -> Not Applicable | N3: =(Table8[[#This Row],[Garage_Out_Date]]-Table8[[#This Row],[Garage_In_Date]]) -> 3.6 | O3: =IF(Table8[[#This Row],[Total_VOR_Days]] >3.5, "Yes", "No") -> Yes | P3: =IF(Table8[[#This Row],[Vehicle_Type]] <> "Specialised", "Not Applicable", IF(AND(Table8[[#This Row],[Hours_To_Book]] <=48, Table8[[#This Row],[Total_VOR_Days]] >3.5), "Ineffective", "Effective")) -> Not Applicable | Q3: =IF(OR(Table8[[#This Row],[Garage_In_Date]]="",Table8[[#This Row],[Actual_Repair_Start_Date]]=""),"N/A",(Table8[[#This Row],[Actual_Repair_Start_Date]]-Table8[[#This Row],[Garage_In_Date]])*24) -> 4 | R3: =_xlfn.XLOOKUP(Table8[[#This Row],[Vehicle_ID]],Table5[Vehicle_ID],Table5[MOT_Linked],"Not Found") -> No
A4: VH1002 | B4: Standard | C4: Mercedes Atego | D4: 46081.552 | E4: 46083.415 | F4: 46083.748 | G4: 46088.948 | H4: 46083.915 | I4: 46087 | J4: Garage Capacity / Ramp Delay | K4: Central Perk Repairs | L4: =(Table8[[#This Row],[Garage_Booked_DateTime]] - Table8[[#This Row],[Defect_Reported_DateTime]])*24 -> 44.7 | M4: =IF(Table8[[#This Row],[Vehicle_Type]]<>"Specialised", "Not Applicable", IF(Table8[[#This Row],[Hours_To_Book]]>48, "Yes", "No")) -> Not Applicable | N4: =(Table8[[#This Row],[Garage_Out_Date]]-Table8[[#This Row],[Garage_In_Date]]) -> 5.2 | O4: =IF(Table8[[#This Row],[Total_VOR_Days]] >3.5, "Yes", "No") -> Yes | P4: =IF(Table8[[#This Row],[Vehicle_Type]] <> "Specialised", "Not Applicable", IF(AND(Table8[[#This Row],[Hours_To_Book]] <=48, Table8[[#This Row],[Total_VOR_Days]] >3.5), "Ineffective", "Effective")) -> Not Applicable | Q4: =IF(OR(Table8[[#This Row],[Garage_In_Date]]="",Table8[[#This Row],[Actual_Repair_Start_Date]]=""),"N/A",(Table8[[#This Row],[Actual_Repair_Start_Date]]-Table8[[#This Row],[Garage_In_Date]])*24) -> 4 | R4: =_xlfn.XLOOKUP(Table8[[#This Row],[Vehicle_ID]],Table5[Vehicle_ID],Table5[MOT_Linked],"Not Found") -> No
A5: VH1003 | B5: Specialised | C5: Iveco Daily | D5: 46082.604 | E5: 46084.317 | F5: 46085.817 | G5: 46089.817 | H5: 46085.983 | I5: 46088 | J5: Incorrect Job Scoping | K5: 15 Yemen Rd Garage | L5: =(Table8[[#This Row],[Garage_Booked_DateTime]] - Table8[[#This Row],[Defect_Reported_DateTime]])*24 -> 41.1 | M5: =IF(Table8[[#This Row],[Vehicle_Type]]<>"Specialised", "Not Applicable", IF(Table8[[#This Row],[Hours_To_Book]]>48, "Yes", "No")) -> No | N5: =(Table8[[#This Row],[Garage_Out_Date]]-Table8[[#This Row],[Garage_In_Date]]) -> 4 | O5: =IF(Table8[[#This Row],[Total_VOR_Days]] >3.5, "Yes", "No") -> Yes | P5: =IF(Table8[[#This Row],[Vehicle_Type]] <> "Specialised", "Not Applicable", IF(AND(Table8[[#This Row],[Hours_To_Book]] <=48, Table8[[#This Row],[Total_VOR_Days]] >3.5), "Ineffective", "Effective")) -> Ineffective | Q5: =IF(OR(Table8[[#This Row],[Garage_In_Date]]="",Table8[[#This Row],[Actual_Repair_Start_Date]]=""),"N/A",(Table8[[#This Row],[Actual_Repair_Start_Date]]-Table8[[#This Row],[Garage_In_Date]])*24) -> 4 | R5: =_xlfn.XLOOKUP(Table8[[#This Row],[Vehicle_ID]],Table5[Vehicle_ID],Table5[MOT_Linked],"Not Found") -> No
A6: VH1004 | B6: Specialised | C6: Iveco Daily | D6: 46031.479 | E6: 46032.783 | F6: 46034.783 | G6: 46041.283 | H6: 46035.354 | I6: 46039 | J6: Awaiting Client Authorization | K6: Joey Special Auto Centre | L6: =(Table8[[#This Row],[Garage_Booked_DateTime]] - Table8[[#This Row],[Defect_Reported_DateTime]])*24 -> 31.3 | M6: =IF(Table8[[#This Row],[Vehicle_Type]]<>"Specialised", "Not Applicable", IF(Table8[[#This Row],[Hours_To_Book]]>48, "Yes", "No")) -> No | N6: =(Table8[[#This Row],[Garage_Out_Date]]-Table8[[#This Row],[Garage_In_Date]]) -> 6.5 | O6: =IF(Table8[[#This Row],[Total_VOR_Days]] >3.5, "Yes", "No") -> Yes | P6: =IF(Table8[[#This Row],[Vehicle_Type]] <> "Specialised", "Not Applicable", IF(AND(Table8[[#This Row],[Hours_To_Book]] <=48, Table8[[#This Row],[Total_VOR_Days]] >3.5), "Ineffective", "Effective")) -> Ineffective | Q6: =IF(OR(Table8[[#This Row],[Garage_In_Date]]="",Table8[[#This Row],[Actual_Repair_Start_Date]]=""),"N/A",(Table8[[#This Row],[Actual_Repair_Start_Date]]-Table8[[#This Row],[Garage_In_Date]])*24) -> 13.7 | R6: =_xlfn.XLOOKUP(Table8[[#This Row],[Vehicle_ID]],Table5[Vehicle_ID],Table5[MOT_Linked],"Not Found") -> No
A7: VH1005 | B7: Standard | C7: Vauxhall Vivaro | D7: 46097.615 | E7: 46097.948 | F7: 46098.115 | G7: 46107.515 | H7: 46098.115 | I7: 46106 | J7: Parts on Backorder | K7: Princess Consuela Auto Centre | L7: =(Table8[[#This Row],[Garage_Booked_DateTime]] - Table8[[#This Row],[Defect_Reported_DateTime]])*24 -> 8 | M7: =IF(Table8[[#This Row],[Vehicle_Type]]<>"Specialised", "Not Applicable", IF(Table8[[#This Row],[Hours_To_Book]]>48, "Yes", "No")) -> Not Applicable | N7: =(Table8[[#This Row],[Garage_Out_Date]]-Table8[[#This Row],[Garage_In_Date]]) -> 9.4 | O7: =IF(Table8[[#This Row],[Total_VOR_Days]] >3.5, "Yes", "No") -> Yes | P7: =IF(Table8[[#This Row],[Vehicle_Type]] <> "Specialised", "Not Applicable", IF(AND(Table8[[#This Row],[Hours_To_Book]] <=48, Table8[[#This Row],[Total_VOR_Days]] >3.5), "Ineffective", "Effective")) -> Not Applicable | Q7: =IF(OR(Table8[[#This Row],[Garage_In_Date]]="",Table8[[#This Row],[Actual_Repair_Start_Date]]=""),"N/A",(Table8[[#This Row],[Actual_Repair_Start_Date]]-Table8[[#This Row],[Garage_In_Date]])*24) -> 0 | R7: =_xlfn.XLOOKUP(Table8[[#This Row],[Vehicle_ID]],Table5[Vehicle_ID],Table5[MOT_Linked],"Not Found") -> Yes
A8: VH1006 | B8: Standard | C8: Vauxhall Vivaro | D8: 46077.708 | E8: 46079.075 | F8: 46080.075 | G8: 46086.075 | H8: 46080.396 | I8: 46085 | J8: Incorrect Job Scoping | K8: PIVOT Garage Repairs | L8: =(Table8[[#This Row],[Garage_Booked_DateTime]] - Table8[[#This Row],[Defect_Reported_DateTime]])*24 -> 32.8 | M8: =IF(Table8[[#This Row],[Vehicle_Type]]<>"Specialised", "Not Applicable", IF(Table8[[#This Row],[Hours_To_Book]]>48, "Yes", "No")) -> Not Applicable | N8: =(Table8[[#This Row],[Garage_Out_Date]]-Table8[[#This Row],[Garage_In_Date]]) -> 6 | O8: =IF(Table8[[#This Row],[Total_VOR_Days]] >3.5, "Yes", "No") -> Yes | P8: =IF(Table8[[#This Row],[Vehicle_Type]] <> "Specialised", "Not Applicable", IF(AND(Table8[[#This Row],[Hours_To_Book]] <=48, Table8[[#This Row],[Total_VOR_Days]] >3.5), "Ineffective", "Effective")) -> Not Applicable | Q8: =IF(OR(Table8[[#This Row],[Garage_In_Date]]="",Table8[[#This Row],[Actual_Repair_Start_Date]]=""),"N/A",(Table8[[#This Row],[Actual_Repair_Start_Date]]-Table8[[#This Row],[Garage_In_Date]])*24) -> 7.7 | R8: =_xlfn.XLOOKUP(Table8[[#This Row],[Vehicle_ID]],Table5[Vehicle_ID],Table5[MOT_Linked],"Not Found") -> No
A9: VH1007 | B9: Standard | C9: Vauxhall Vivaro | D9: 46136.688 | E9: 46139.075 | F9: 46139.408 | G9: 46141.808 | H9: 46139.408 | I9: 46140 | J9: None (On Time) | K9: Joey Special Auto Centre | L9: =(Table8[[#This Row],[Garage_Booked_DateTime]] - Table8[[#This Row],[Defect_Reported_DateTime]])*24 -> 57.3 | M9: =IF(Table8[[#This Row],[Vehicle_Type]]<>"Specialised", "Not Applicable", IF(Table8[[#This Row],[Hours_To_Book]]>48, "Yes", "No")) -> Not Applicable | N9: =(Table8[[#This Row],[Garage_Out_Date]]-Table8[[#This Row],[Garage_In_Date]]) -> 2.4 | O9: =IF(Table8[[#This Row],[Total_VOR_Days]] >3.5, "Yes", "No") -> No | P9: =IF(Table8[[#This Row],[Vehicle_Type]] <> "Specialised", "Not Applicable", IF(AND(Table8[[#This Row],[Hours_To_Book]] <=48, Table8[[#This Row],[Total_VOR_Days]] >3.5), "Ineffective", "Effective")) -> Not Applicable | Q9: =IF(OR(Table8[[#This Row],[Garage_In_Date]]="",Table8[[#This Row],[Actual_Repair_Start_Date]]=""),"N/A",(Table8[[#This Row],[Actual_Repair_Start_Date]]-Table8[[#This Row],[Garage_In_Date]])*24) -> 0 | R9: =_xlfn.XLOOKUP(Table8[[#This Row],[Vehicle_ID]],Table5[Vehicle_ID],Table5[MOT_Linked],"Not Found") -> No
A10: VH1008 | B10: Standard | C10: Vauxhall Movano | D10: 46120.417 | E10: 46123.238 | F10: 46125.238 | G10: 46128.238 | H10: 46125.404 | I10: 46128 | J10: None (On Time) | K10: Central Perk Repairs | L10: =(Table8[[#This Row],[Garage_Booked_DateTime]] - Table8[[#This Row],[Defect_Reported_DateTime]])*24 -> 67.7 | M10: =IF(Table8[[#This Row],[Vehicle_Type]]<>"Specialised", "Not Applicable", IF(Table8[[#This Row],[Hours_To_Book]]>48, "Yes", "No")) -> Not Applicable | N10: =(Table8[[#This Row],[Garage_Out_Date]]-Table8[[#This Row],[Garage_In_Date]]) -> 3 | O10: =IF(Table8[[#This Row],[Total_VOR_Days]] >3.5, "Yes", "No") -> No | P10: =IF(Table8[[#This Row],[Vehicle_Type]] <> "Specialised", "Not Applicable", IF(AND(Table8[[#This Row],[Hours_To_Book]] <=48, Table8[[#This Row],[Total_VOR_Days]] >3.5), "Ineffective", "Effective")) -> Not Applicable | Q10: =IF(OR(Table8[[#This Row],[Garage_In_Date]]="",Table8[[#This Row],[Actual_Repair_Start_Date]]=""),"N/A",(Table8[[#This Row],[Actual_Repair_Start_Date]]-Table8[[#This Row],[Garage_In_Date]])*24) -> 4 | R10: =_xlfn.XLOOKUP(Table8[[#This Row],[Vehicle_ID]],Table5[Vehicle_ID],Table5[MOT_Linked],"Not Found") -> Yes | T10: =_xlfn.XLOOKUP("Joey Special Auto Centre", Table8[Garage_Name], Table8[Total_VOR_Days]) -> 2
A11: VH1009 | B11: Standard | C11: Ford Transit | D11: 46099.573 | E11: 46103.956 | F11: 46104.29 | G11: 46109.09 | H11: 46107.417 | I11: 46110 | J11: Garage Capacity / Ramp Delay | K11: Dr Drake Ramoray Autos | L11: =(Table8[[#This Row],[Garage_Booked_DateTime]] - Table8[[#This Row],[Defect_Reported_DateTime]])*24 -> 105.2 | M11: =IF(Table8[[#This Row],[Vehicle_Type]]<>"Specialised", "Not Applicable", IF(Table8[[#This Row],[Hours_To_Book]]>48, "Yes", "No")) -> Not Applicable | N11: =(Table8[[#This Row],[Garage_Out_Date]]-Table8[[#This Row],[Garage_In_Date]]) -> 4.8 | O11: =IF(Table8[[#This Row],[Total_VOR_Days]] >3.5, "Yes", "No") -> Yes | P11: =IF(Table8[[#This Row],[Vehicle_Type]] <> "Specialised", "Not Applicable", IF(AND(Table8[[#This Row],[Hours_To_Book]] <=48, Table8[[#This Row],[Total_VOR_Days]] >3.5), "Ineffective", "Effective")) -> Not Applicable | Q11: =IF(OR(Table8[[#This Row],[Garage_In_Date]]="",Table8[[#This Row],[Actual_Repair_Start_Date]]=""),"N/A",(Table8[[#This Row],[Actual_Repair_Start_Date]]-Table8[[#This Row],[Garage_In_Date]])*24) -> 75.05 | R11: =_xlfn.XLOOKUP(Table8[[#This Row],[Vehicle_ID]],Table5[Vehicle_ID],Table5[MOT_Linked],"Not Found") -> No
A12: VH1010 | B12: Standard | C12: Ford Transit | D12: 46120.677 | E12: 46123.69 | F12: 46125.19 | G12: 46130.99 | H12: 46125.385 | I12: 46130 | J12: Parts on Backorder | K12: Central Perk Repairs | L12: =(Table8[[#This Row],[Garage_Booked_DateTime]] - Table8[[#This Row],[Defect_Reported_DateTime]])*24 -> 72.3 | M12: =IF(Table8[[#This Row],[Vehicle_Type]]<>"Specialised", "Not Applicable", IF(Table8[[#This Row],[Hours_To_Book]]>48, "Yes", "No")) -> Not Applicable | N12: =(Table8[[#This Row],[Garage_Out_Date]]-Table8[[#This Row],[Garage_In_Date]]) -> 5.8 | O12: =IF(Table8[[#This Row],[Total_VOR_Days]] >3.5, "Yes", "No") -> Yes | P12: =IF(Table8[[#This Row],[Vehicle_Type]] <> "Specialised", "Not Applicable", IF(AND(Table8[[#This Row],[Hours_To_Book]] <=48, Table8[[#This Row],[Total_VOR_Days]] >3.5), "Ineffective", "Effective")) -> Not Applicable | Q12: =IF(OR(Table8[[#This Row],[Garage_In_Date]]="",Table8[[#This Row],[Actual_Repair_Start_Date]]=""),"N/A",(Table8[[#This Row],[Actual_Repair_Start_Date]]-Table8[[#This Row],[Garage_In_Date]])*24) -> 4.7 | R12: =_xlfn.XLOOKUP(Table8[[#This Row],[Vehicle_ID]],Table5[Vehicle_ID],Table5[MOT_Linked],"Not Found") -> No | S12: Avg VOR (Parts on Backorder) | T12: =AVERAGEIF(Table8[Primary_Delay_Reason],"Parts on Backorder",Table8[Total_VOR_Days]) -> 6.2
A13: VH1011 | B13: Specialised | C13: Mercedes Atego | D13: 46114.531 | E13: 46116.252 | F13: 46117.252 | G13: 46121.352 | H13: 46117.252 | I13: 46119 | J13: Parts on Backorder | K13: 15 Yemen Rd Garage | L13: =(Table8[[#This Row],[Garage_Booked_DateTime]] - Table8[[#This Row],[Defect_Reported_DateTime]])*24 -> 41.3 | M13: =IF(Table8[[#This Row],[Vehicle_Type]]<>"Specialised", "Not Applicable", IF(Table8[[#This Row],[Hours_To_Book]]>48, "Yes", "No")) -> No | N13: =(Table8[[#This Row],[Garage_Out_Date]]-Table8[[#This Row],[Garage_In_Date]]) -> 4.1 | O13: =IF(Table8[[#This Row],[Total_VOR_Days]] >3.5, "Yes", "No") -> Yes | P13: =IF(Table8[[#This Row],[Vehicle_Type]] <> "Specialised", "Not Applicable", IF(AND(Table8[[#This Row],[Hours_To_Book]] <=48, Table8[[#This Row],[Total_VOR_Days]] >3.5), "Ineffective", "Effective")) -> Ineffective | Q13: =IF(OR(Table8[[#This Row],[Garage_In_Date]]="",Table8[[#This Row],[Actual_Repair_Start_Date]]=""),"N/A",(Table8[[#This Row],[Actual_Repair_Start_Date]]-Table8[[#This Row],[Garage_In_Date]])*24) -> 0 | R13: =_xlfn.XLOOKUP(Table8[[#This Row],[Vehicle_ID]],Table5[Vehicle_ID],Table5[MOT_Linked],"Not Found") -> No
A14: VH1012 | B14: Standard | C14: Vauxhall Movano | D14: 46093.469 | E14: 46097.198 | F14: 46097.198 | G14: 46101.498 | H14: 46097.365 | I14: 46100 | J14: Garage Capacity / Ramp Delay | K14: Mississippilessly Repairs | L14: =(Table8[[#This Row],[Garage_Booked_DateTime]] - Table8[[#This Row],[Defect_Reported_DateTime]])*24 -> 89.5 | M14: =IF(Table8[[#This Row],[Vehicle_Type]]<>"Specialised", "Not Applicable", IF(Table8[[#This Row],[Hours_To_Book]]>48, "Yes", "No")) -> Not Applicable | N14: =(Table8[[#This Row],[Garage_Out_Date]]-Table8[[#This Row],[Garage_In_Date]]) -> 4.3 | O14: =IF(Table8[[#This Row],[Total_VOR_Days]] >3.5, "Yes", "No") -> Yes | P14: =IF(Table8[[#This Row],[Vehicle_Type]] <> "Specialised", "Not Applicable", IF(AND(Table8[[#This Row],[Hours_To_Book]] <=48, Table8[[#This Row],[Total_VOR_Days]] >3.5), "Ineffective", "Effective")) -> Not Applicable | Q14: =IF(OR(Table8[[#This Row],[Garage_In_Date]]="",Table8[[#This Row],[Actual_Repair_Start_Date]]=""),"N/A",(Table8[[#This Row],[Actual_Repair_Start_Date]]-Table8[[#This Row],[Garage_In_Date]])*24) -> 4 | R14: =_xlfn.XLOOKUP(Table8[[#This Row],[Vehicle_ID]],Table5[Vehicle_ID],Table5[MOT_Linked],"Not Found") -> 0
A15: VH1013 | B15: Specialised | C15: Mercedes Atego | D15: 46050.677 | E15: 46051.765 | F15: 46053.265 | G15: 46053.765 | H15: 46053.265 | I15: 46053 | J15: None (On Time) | K15: PIVOT Garage Repairs | L15: =(Table8[[#This Row],[Garage_Booked_DateTime]] - Table8[[#This Row],[Defect_Reported_DateTime]])*24 -> 26.1 | M15: =IF(Table8[[#This Row],[Vehicle_Type]]<>"Specialised", "Not Applicable", IF(Table8[[#This Row],[Hours_To_Book]]>48, "Yes", "No")) -> No | N15: =(Table8[[#This Row],[Garage_Out_Date]]-Table8[[#This Row],[Garage_In_Date]]) -> 0.5 | O15: =IF(Table8[[#This Row],[Total_VOR_Days]] >3.5, "Yes", "No") -> No | P15: =IF(Table8[[#This Row],[Vehicle_Type]] <> "Specialised", "Not Applicable", IF(AND(Table8[[#This Row],[Hours_To_Book]] <=48, Table8[[#This Row],[Total_VOR_Days]] >3.5), "Ineffective", "Effective")) -> Effective | Q15: =IF(OR(Table8[[#This Row],[Garage_In_Date]]="",Table8[[#This Row],[Actual_Repair_Start_Date]]=""),"N/A",(Table8[[#This Row],[Actual_Repair_Start_Date]]-Table8[[#This Row],[Garage_In_Date]])*24) -> 0 | R15: =_xlfn.XLOOKUP(Table8[[#This Row],[Vehicle_ID]],Table5[Vehicle_ID],Table5[MOT_Linked],"Not Found") -> No
A16: VH1014 | B16: Specialised | C16: Iveco Daily | D16: 46077.615 | E16: 46078.902 | F16: 46080.902 | G16: 46084.602 | H16: 46080.902 | I16: 46082 | J16: Parts on Backorder | K16: PIVOT Garage Repairs | L16: =(Table8[[#This Row],[Garage_Booked_DateTime]] - Table8[[#This Row],[Defect_Reported_DateTime]])*24 -> 30.9 | M16: =IF(Table8[[#This Row],[Vehicle_Type]]<>"Specialised", "Not Applicable", IF(Table8[[#This Row],[Hours_To_Book]]>48, "Yes", "No")) -> No | N16: =(Table8[[#This Row],[Garage_Out_Date]]-Table8[[#This Row],[Garage_In_Date]]) -> 3.7 | O16: =IF(Table8[[#This Row],[Total_VOR_Days]] >3.5, "Yes", "No") -> Yes | P16: =IF(Table8[[#This Row],[Vehicle_Type]] <> "Specialised", "Not Applicable", IF(AND(Table8[[#This Row],[Hours_To_Book]] <=48, Table8[[#This Row],[Total_VOR_Days]] >3.5), "Ineffective", "Effective")) -> Ineffective | Q16: =IF(OR(Table8[[#This Row],[Garage_In_Date]]="",Table8[[#This Row],[Actual_Repair_Start_Date]]=""),"N/A",(Table8[[#This Row],[Actual_Repair_Start_Date]]-Table8[[#This Row],[Garage_In_Date]])*24) -> 0 | R16: =_xlfn.XLOOKUP(Table8[[#This Row],[Vehicle_ID]],Table5[Vehicle_ID],Table5[MOT_Linked],"Not Found") -> Yes
A17: VH1015 | B17: Standard | C17: Iveco Daily | D17: 46047.49 | E17: 46050.152 | F17: 46051.152 | G17: 46056.352 | H17: 46051.319 | I17: 46056 | J17: Garage Capacity / Ramp Delay | K17: Central Perk Repairs | L17: =(Table8[[#This Row],[Garage_Booked_DateTime]] - Table8[[#This Row],[Defect_Reported_DateTime]])*24 -> 63.9 | M17: =IF(Table8[[#This Row],[Vehicle_Type]]<>"Specialised", "Not Applicable", IF(Table8[[#This Row],[Hours_To_Book]]>48, "Yes", "No")) -> Not Applicable | N17: =(Table8[[#This Row],[Garage_Out_Date]]-Table8[[#This Row],[Garage_In_Date]]) -> 5.2 | O17: =IF(Table8[[#This Row],[Total_VOR_Days]] >3.5, "Yes", "No") -> Yes | P17: =IF(Table8[[#This Row],[Vehicle_Type]] <> "Specialised", "Not Applicable", IF(AND(Table8[[#This Row],[Hours_To_Book]] <=48, Table8[[#This Row],[Total_VOR_Days]] >3.5), "Ineffective", "Effective")) -> Not Applicable | Q17: =IF(OR(Table8[[#This Row],[Garage_In_Date]]="",Table8[[#This Row],[Actual_Repair_Start_Date]]=""),"N/A",(Table8[[#This Row],[Actual_Repair_Start_Date]]-Table8[[#This Row],[Garage_In_Date]])*24) -> 4 | R17: =_xlfn.XLOOKUP(Table8[[#This Row],[Vehicle_ID]],Table5[Vehicle_ID],Table5[MOT_Linked],"Not Found") -> No
A18: VH1016 | B18: Standard | C18: Ford Transit | D18: 46029.667 | E18: 46034.012 | F18: 46034.179 | G18: 46037.479 | H18: 46036.354 | I18: 46035 | J18: None (On Time) | K18: 15 Yemen Rd Garage | L18: =(Table8[[#This Row],[Garage_Booked_DateTime]] - Table8[[#This Row],[Defect_Reported_DateTime]])*24 -> 104.3 | M18: =IF(Table8[[#This Row],[Vehicle_Type]]<>"Specialised", "Not Applicable", IF(Table8[[#This Row],[Hours_To_Book]]>48, "Yes", "No")) -> Not Applicable | N18: =(Table8[[#This Row],[Garage_Out_Date]]-Table8[[#This Row],[Garage_In_Date]]) -> 3.3 | O18: =IF(Table8[[#This Row],[Total_VOR_Days]] >3.5, "Yes", "No") -> No | P18: =IF(Table8[[#This Row],[Vehicle_Type]] <> "Specialised", "Not Applicable", IF(AND(Table8[[#This Row],[Hours_To_Book]] <=48, Table8[[#This Row],[Total_VOR_Days]] >3.5), "Ineffective", "Effective")) -> Not Applicable | Q18: =IF(OR(Table8[[#This Row],[Garage_In_Date]]="",Table8[[#This Row],[Actual_Repair_Start_Date]]=""),"N/A",(Table8[[#This Row],[Actual_Repair_Start_Date]]-Table8[[#This Row],[Garage_In_Date]])*24) -> 52.2 | R18: =_xlfn.XLOOKUP(Table8[[#This Row],[Vehicle_ID]],Table5[Vehicle_ID],Table5[MOT_Linked],"Not Found") -> No
A19: VH1017 | B19: Specialised | C19: Iveco Daily | D19: 46072.531 | E19: 46073.619 | F19: 46075.619 | G19: 46082.819 | J19: Unknown / Insufficient Data | K19: Joey Special Auto Centre | L19: =(Table8[[#This Row],[Garage_Booked_DateTime]] - Table8[[#This Row],[Defect_Reported_DateTime]])*24 -> 26.1 | M19: =IF(Table8[[#This Row],[Vehicle_Type]]<>"Specialised", "Not Applicable", IF(Table8[[#This Row],[Hours_To_Book]]>48, "Yes", "No")) -> No | N19: =(Table8[[#This Row],[Garage_Out_Date]]-Table8[[#This Row],[Garage_In_Date]]) -> 7.2 | O19: =IF(Table8[[#This Row],[Total_VOR_Days]] >3.5, "Yes", "No") -> Yes | P19: =IF(Table8[[#This Row],[Vehicle_Type]] <> "Specialised", "Not Applicable", IF(AND(Table8[[#This Row],[Hours_To_Book]] <=48, Table8[[#This Row],[Total_VOR_Days]] >3.5), "Ineffective", "Effective")) -> Ineffective | Q19: =IF(OR(Table8[[#This Row],[Garage_In_Date]]="",Table8[[#This Row],[Actual_Repair_Start_Date]]=""),"N/A",(Table8[[#This Row],[Actual_Repair_Start_Date]]-Table8[[#This Row],[Garage_In_Date]])*24) -> N/A | R19: =_xlfn.XLOOKUP(Table8[[#This Row],[Vehicle_ID]],Table5[Vehicle_ID],Table5[MOT_Linked],"Not Found") -> No
A20: VH1018 | B20: Standard | C20: Iveco Daily | D20: 46030.708 | E20: 46032.996 | F20: 46034.496 | G20: 46037.996 | H20: 46036.438 | I20: 46036 | J20: None (On Time) | K20: Central Perk Repairs | L20: =(Table8[[#This Row],[Garage_Booked_DateTime]] - Table8[[#This Row],[Defect_Reported_DateTime]])*24 -> 54.9 | M20: =IF(Table8[[#This Row],[Vehicle_Type]]<>"Specialised", "Not Applicable", IF(Table8[[#This Row],[Hours_To_Book]]>48, "Yes", "No")) -> Not Applicable | N20: =(Table8[[#This Row],[Garage_Out_Date]]-Table8[[#This Row],[Garage_In_Date]]) -> 3.5 | O20: =IF(Table8[[#This Row],[Total_VOR_Days]] >3.5, "Yes", "No") -> No | P20: =IF(Table8[[#This Row],[Vehicle_Type]] <> "Specialised", "Not Applicable", IF(AND(Table8[[#This Row],[Hours_To_Book]] <=48, Table8[[#This Row],[Total_VOR_Days]] >3.5), "Ineffective", "Effective")) -> Not Applicable | Q20: =IF(OR(Table8[[#This Row],[Garage_In_Date]]="",Table8[[#This Row],[Actual_Repair_Start_Date]]=""),"N/A",(Table8[[#This Row],[Actual_Repair_Start_Date]]-Table8[[#This Row],[Garage_In_Date]])*24) -> 46.6 | R20: =_xlfn.XLOOKUP(Table8[[#This Row],[Vehicle_ID]],Table5[Vehicle_ID],Table5[MOT_Linked],"Not Found") -> No
A21: VH1019 | B21: Specialised | C21: Vauxhall Movano | D21: 46031.708 | E21: 46032.8 | F21: 46032.8 | G21: 46035.7 | H21: 46033.167 | I21: 46034 | J21: None (On Time) | K21: PIVOT Garage Repairs | L21: =(Table8[[#This Row],[Garage_Booked_DateTime]] - Table8[[#This Row],[Defect_Reported_DateTime]])*24 -> 26.2 | M21: =IF(Table8[[#This Row],[Vehicle_Type]]<>"Specialised", "Not Applicable", IF(Table8[[#This Row],[Hours_To_Book]]>48, "Yes", "No")) -> No | N21: =(Table8[[#This Row],[Garage_Out_Date]]-Table8[[#This Row],[Garage_In_Date]]) -> 2.9 | O21: =IF(Table8[[#This Row],[Total_VOR_Days]] >3.5, "Yes", "No") -> No | P21: =IF(Table8[[#This Row],[Vehicle_Type]] <> "Specialised", "Not Applicable", IF(AND(Table8[[#This Row],[Hours_To_Book]] <=48, Table8[[#This Row],[Total_VOR_Days]] >3.5), "Ineffective", "Effective")) -> Effective | Q21: =IF(OR(Table8[[#This Row],[Garage_In_Date]]="",Table8[[#This Row],[Actual_Repair_Start_Date]]=""),"N/A",(Table8[[#This Row],[Actual_Repair_Start_Date]]-Table8[[#This Row],[Garage_In_Date]])*24) -> 8.8 | R21: =_xlfn.XLOOKUP(Table8[[#This Row],[Vehicle_ID]],Table5[Vehicle_ID],Table5[MOT_Linked],"Not Found") -> No
A22: VH1020 | B22: Specialised | C22: Mercedes Atego | D22: 46095.688 | E22: 46097.117 | F22: 46099.117 | G22: 46102.817 | H22: 46100.438 | I22: 46101 | J22: Garage Capacity / Ramp Delay | K22: Dr Drake Ramoray Autos | L22: =(Table8[[#This Row],[Garage_Booked_DateTime]] - Table8[[#This Row],[Defect_Reported_DateTime]])*24 -> 34.3 | M22: =IF(Table8[[#This Row],[Vehicle_Type]]<>"Specialised", "Not Applicable", IF(Table8[[#This Row],[Hours_To_Book]]>48, "Yes", "No")) -> No | N22: =(Table8[[#This Row],[Garage_Out_Date]]-Table8[[#This Row],[Garage_In_Date]]) -> 3.7 | O22: =IF(Table8[[#This Row],[Total_VOR_Days]] >3.5, "Yes", "No") -> Yes | P22: =IF(Table8[[#This Row],[Vehicle_Type]] <> "Specialised", "Not Applicable", IF(AND(Table8[[#This Row],[Hours_To_Book]] <=48, Table8[[#This Row],[Total_VOR_Days]] >3.5), "Ineffective", "Effective")) -> Ineffective | Q22: =IF(OR(Table8[[#This Row],[Garage_In_Date]]="",Table8[[#This Row],[Actual_Repair_Start_Date]]=""),"N/A",(Table8[[#This Row],[Actual_Repair_Start_Date]]-Table8[[#This Row],[Garage_In_Date]])*24) -> 31.7 | R22: =_xlfn.XLOOKUP(Table8[[#This Row],[Vehicle_ID]],Table5[Vehicle_ID],Table5[MOT_Linked],"Not Found") -> No
A23: VH1021 | B23: Standard | C23: Mercedes Atego | D23: 46141.375 | E23: 46141.708 | F23: 46141.708 | G23: 46151.808 | H23: 46142.375 | I23: 46151 | J23: Incorrect Job Scoping | K23: Mississippilessly Repairs | L23: =(Table8[[#This Row],[Garage_Booked_DateTime]] - Table8[[#This Row],[Defect_Reported_DateTime]])*24 -> 8 | M23: =IF(Table8[[#This Row],[Vehicle_Type]]<>"Specialised", "Not Applicable", IF(Table8[[#This Row],[Hours_To_Book]]>48, "Yes", "No")) -> Not Applicable | N23: =(Table8[[#This Row],[Garage_Out_Date]]-Table8[[#This Row],[Garage_In_Date]]) -> 10.1 | O23: =IF(Table8[[#This Row],[Total_VOR_Days]] >3.5, "Yes", "No") -> Yes | P23: =IF(Table8[[#This Row],[Vehicle_Type]] <> "Specialised", "Not Applicable", IF(AND(Table8[[#This Row],[Hours_To_Book]] <=48, Table8[[#This Row],[Total_VOR_Days]] >3.5), "Ineffective", "Effective")) -> Not Applicable | Q23: =IF(OR(Table8[[#This Row],[Garage_In_Date]]="",Table8[[#This Row],[Actual_Repair_Start_Date]]=""),"N/A",(Table8[[#This Row],[Actual_Repair_Start_Date]]-Table8[[#This Row],[Garage_In_Date]])*24) -> 16 | R23: =_xlfn.XLOOKUP(Table8[[#This Row],[Vehicle_ID]],Table5[Vehicle_ID],Table5[MOT_Linked],"Not Found") -> No
A24: VH1022 | B24: Standard | C24: Mercedes Atego | D24: 46059.448 | E24: 46062.456 | F24: 46063.956 | G24: 46065.456 | H24: 46064.354 | I24: 46064 | J24: None (On Time) | K24: Central Perk Repairs | L24: =(Table8[[#This Row],[Garage_Booked_DateTime]] - Table8[[#This Row],[Defect_Reported_DateTime]])*24 -> 72.2 | M24: =IF(Table8[[#This Row],[Vehicle_Type]]<>"Specialised", "Not Applicable", IF(Table8[[#This Row],[Hours_To_Book]]>48, "Yes", "No")) -> Not Applicable | N24: =(Table8[[#This Row],[Garage_Out_Date]]-Table8[[#This Row],[Garage_In_Date]]) -> 1.5 | O24: =IF(Table8[[#This Row],[Total_VOR_Days]] >3.5, "Yes", "No") -> No | P24: =IF(Table8[[#This Row],[Vehicle_Type]] <> "Specialised", "Not Applicable", IF(AND(Table8[[#This Row],[Hours_To_Book]] <=48, Table8[[#This Row],[Total_VOR_Days]] >3.5), "Ineffective", "Effective")) -> Not Applicable | Q24: =IF(OR(Table8[[#This Row],[Garage_In_Date]]="",Table8[[#This Row],[Actual_Repair_Start_Date]]=""),"N/A",(Table8[[#This Row],[Actual_Repair_Start_Date]]-Table8[[#This Row],[Garage_In_Date]])*24) -> 9.55 | R24: =_xlfn.XLOOKUP(Table8[[#This Row],[Vehicle_ID]],Table5[Vehicle_ID],Table5[MOT_Linked],"Not Found") -> No
A25: VH1023 | B25: Standard | C25: Mercedes Atego | D25: 46142.385 | E25: 46144.502 | F25: 46146.502 | G25: 46154.902 | H25: 46146.502 | I25: 46153 | J25: Unknown / Insufficient Data | K25: Mississippilessly Repairs | L25: =(Table8[[#This Row],[Garage_Booked_DateTime]] - Table8[[#This Row],[Defect_Reported_DateTime]])*24 -> 50.8 | M25: =IF(Table8[[#This Row],[Vehicle_Type]]<>"Specialised", "Not Applicable", IF(Table8[[#This Row],[Hours_To_Book]]>48, "Yes", "No")) -> Not Applicable | N25: =(Table8[[#This Row],[Garage_Out_Date]]-Table8[[#This Row],[Garage_In_Date]]) -> 8.4 | O25: =IF(Table8[[#This Row],[Total_VOR_Days]] >3.5, "Yes", "No") -> Yes | P25: =IF(Table8[[#This Row],[Vehicle_Type]] <> "Specialised", "Not Applicable", IF(AND(Table8[[#This Row],[Hours_To_Book]] <=48, Table8[[#This Row],[Total_VOR_Days]] >3.5), "Ineffective", "Effective")) -> Not Applicable | Q25: =IF(OR(Table8[[#This Row],[Garage_In_Date]]="",Table8[[#This Row],[Actual_Repair_Start_Date]]=""),"N/A",(Table8[[#This Row],[Actual_Repair_Start_Date]]-Table8[[#This Row],[Garage_In_Date]])*24) -> 0 | R25: =_xlfn.XLOOKUP(Table8[[#This Row],[Vehicle_ID]],Table5[Vehicle_ID],Table5[MOT_Linked],"Not Found") -> No
A26: VH1024 | B26: Standard | C26: Vauxhall Vivaro | D26: 46104.531 | E26: 46106.81 | F26: 46106.81 | G26: 46115.41 | H26: 46106.977 | I26: 46114 | J26: Parts on Backorder | K26: Princess Consuela Auto Centre | L26: =(Table8[[#This Row],[Garage_Booked_DateTime]] - Table8[[#This Row],[Defect_Reported_DateTime]])*24 -> 54.7 | M26: =IF(Table8[[#This Row],[Vehicle_Type]]<>"Specialised", "Not Applicable", IF(Table8[[#This Row],[Hours_To_Book]]>48, "Yes", "No")) -> Not Applicable | N26: =(Table8[[#This Row],[Garage_Out_Date]]-Table8[[#This Row],[Garage_In_Date]]) -> 8.6 | O26: =IF(Table8[[#This Row],[Total_VOR_Days]] >3.5, "Yes", "No") -> Yes | P26: =IF(Table8[[#This Row],[Vehicle_Type]] <> "Specialised", "Not Applicable", IF(AND(Table8[[#This Row],[Hours_To_Book]] <=48, Table8[[#This Row],[Total_VOR_Days]] >3.5), "Ineffective", "Effective")) -> Not Applicable | Q26: =IF(OR(Table8[[#This Row],[Garage_In_Date]]="",Table8[[#This Row],[Actual_Repair_Start_Date]]=""),"N/A",(Table8[[#This Row],[Actual_Repair_Start_Date]]-Table8[[#This Row],[Garage_In_Date]])*24) -> 4 | R26: =_xlfn.XLOOKUP(Table8[[#This Row],[Vehicle_ID]],Table5[Vehicle_ID],Table5[MOT_Linked],"Not Found") -> No
A27: VH1025 | B27: Specialised | C27: Vauxhall Vivaro | D27: 46043.656 | E27: 46044.706 | F27: 46046.706 | G27: 46050.506 | H27: 46046.706 | I27: 46048 | J27: Garage Capacity / Ramp Delay | K27: Princess Consuela Auto Centre | L27: =(Table8[[#This Row],[Garage_Booked_DateTime]] - Table8[[#This Row],[Defect_Reported_DateTime]])*24 -> 25.2 | M27: =IF(Table8[[#This Row],[Vehicle_Type]]<>"Specialised", "Not Applicable", IF(Table8[[#This Row],[Hours_To_Book]]>48, "Yes", "No")) -> No | N27: =(Table8[[#This Row],[Garage_Out_Date]]-Table8[[#This Row],[Garage_In_Date]]) -> 3.8 | O27: =IF(Table8[[#This Row],[Total_VOR_Days]] >3.5, "Yes", "No") -> Yes | P27: =IF(Table8[[#This Row],[Vehicle_Type]] <> "Specialised", "Not Applicable", IF(AND(Table8[[#This Row],[Hours_To_Book]] <=48, Table8[[#This Row],[Total_VOR_Days]] >3.5), "Ineffective", "Effective")) -> Ineffective | Q27: =IF(OR(Table8[[#This Row],[Garage_In_Date]]="",Table8[[#This Row],[Actual_Repair_Start_Date]]=""),"N/A",(Table8[[#This Row],[Actual_Repair_Start_Date]]-Table8[[#This Row],[Garage_In_Date]])*24) -> 0 | R27: =_xlfn.XLOOKUP(Table8[[#This Row],[Vehicle_ID]],Table5[Vehicle_ID],Table5[MOT_Linked],"Not Found") -> No
A28: VH1026 | B28: Standard | C28: Renault Master | D28: 46039.354 | E28: 46040.238 | F28: 46040.238 | G28: 46047.938 | H28: 46041.375 | I28: 46048 | J28: Parts on Backorder | K28: Central Perk Repairs | L28: =(Table8[[#This Row],[Garage_Booked_DateTime]] - Table8[[#This Row],[Defect_Reported_DateTime]])*24 -> 21.2 | M28: =IF(Table8[[#This Row],[Vehicle_Type]]<>"Specialised", "Not Applicable", IF(Table8[[#This Row],[Hours_To_Book]]>48, "Yes", "No")) -> Not Applicable | N28: =(Table8[[#This Row],[Garage_Out_Date]]-Table8[[#This Row],[Garage_In_Date]]) -> 7.7 | O28: =IF(Table8[[#This Row],[Total_VOR_Days]] >3.5, "Yes", "No") -> Yes | P28: =IF(Table8[[#This Row],[Vehicle_Type]] <> "Specialised", "Not Applicable", IF(AND(Table8[[#This Row],[Hours_To_Book]] <=48, Table8[[#This Row],[Total_VOR_Days]] >3.5), "Ineffective", "Effective")) -> Not Applicable | Q28: =IF(OR(Table8[[#This Row],[Garage_In_Date]]="",Table8[[#This Row],[Actual_Repair_Start_Date]]=""),"N/A",(Table8[[#This Row],[Actual_Repair_Start_Date]]-Table8[[#This Row],[Garage_In_Date]])*24) -> 27.3 | R28: =_xlfn.XLOOKUP(Table8[[#This Row],[Vehicle_ID]],Table5[Vehicle_ID],Table5[MOT_Linked],"Not Found") -> No
A29: VH1027 | B29: Specialised | C29: Vauxhall Vivaro | D29: 46118.427 | E29: 46120.273 | F29: 46120.44 | G29: 46120.94 | H29: 46120.44 | I29: 46121 | J29: None (On Time) | K29: Geller Repair Shop | L29: =(Table8[[#This Row],[Garage_Booked_DateTime]] - Table8[[#This Row],[Defect_Reported_DateTime]])*24 -> 44.3 | M29: =IF(Table8[[#This Row],[Vehicle_Type]]<>"Specialised", "Not Applicable", IF(Table8[[#This Row],[Hours_To_Book]]>48, "Yes", "No")) -> No | N29: =(Table8[[#This Row],[Garage_Out_Date]]-Table8[[#This Row],[Garage_In_Date]]) -> 0.5 | O29: =IF(Table8[[#This Row],[Total_VOR_Days]] >3.5, "Yes", "No") -> No | P29: =IF(Table8[[#This Row],[Vehicle_Type]] <> "Specialised", "Not Applicable", IF(AND(Table8[[#This Row],[Hours_To_Book]] <=48, Table8[[#This Row],[Total_VOR_Days]] >3.5), "Ineffective", "Effective")) -> Effective | Q29: =IF(OR(Table8[[#This Row],[Garage_In_Date]]="",Table8[[#This Row],[Actual_Repair_Start_Date]]=""),"N/A",(Table8[[#This Row],[Actual_Repair_Start_Date]]-Table8[[#This Row],[Garage_In_Date]])*24) -> 0 | R29: =_xlfn.XLOOKUP(Table8[[#This Row],[Vehicle_ID]],Table5[Vehicle_ID],Table5[MOT_Linked],"Not Found") -> 0
A30: VH1028 | B30: Specialised | C30: Vauxhall Movano | D30: 46126.479 | E30: 46127.983 | F30: 46128.983 | G30: 46135.783 | H30: 46128.983 | I30: 46133 | J30: Incorrect Job Scoping | K30: Dr Drake Ramoray Autos | L30: =(Table8[[#This Row],[Garage_Booked_DateTime]] - Table8[[#This Row],[Defect_Reported_DateTime]])*24 -> 36.1 | M30: =IF(Table8[[#This Row],[Vehicle_Type]]<>"Specialised", "Not Applicable", IF(Table8[[#This Row],[Hours_To_Book]]>48, "Yes", "No")) -> No | N30: =(Table8[[#This Row],[Garage_Out_Date]]-Table8[[#This Row],[Garage_In_Date]]) -> 6.8 | O30: =IF(Table8[[#This Row],[Total_VOR_Days]] >3.5, "Yes", "No") -> Yes | P30: =IF(Table8[[#This Row],[Vehicle_Type]] <> "Specialised", "Not Applicable", IF(AND(Table8[[#This Row],[Hours_To_Book]] <=48, Table8[[#This Row],[Total_VOR_Days]] >3.5), "Ineffective", "Effective")) -> Ineffective | Q30: =IF(OR(Table8[[#This Row],[Garage_In_Date]]="",Table8[[#This Row],[Actual_Repair_Start_Date]]=""),"N/A",(Table8[[#This Row],[Actual_Repair_Start_Date]]-Table8[[#This Row],[Garage_In_Date]])*24) -> 0 | R30: =_xlfn.XLOOKUP(Table8[[#This Row],[Vehicle_ID]],Table5[Vehicle_ID],Table5[MOT_Linked],"Not Found") -> No
A31: VH1029 | B31: Specialised | C31: Iveco Daily | D31: 46124.469 | E31: 46125.906 | F31: 46126.24 | G31: 46130.64 | H31: 46126.479 | I31: 46128 | J31: Parts on Backorder | K31: Central Perk Repairs | L31: =(Table8[[#This Row],[Garage_Booked_DateTime]] - Table8[[#This Row],[Defect_Reported_DateTime]])*24 -> 34.5 | M31: =IF(Table8[[#This Row],[Vehicle_Type]]<>"Specialised", "Not Applicable", IF(Table8[[#This Row],[Hours_To_Book]]>48, "Yes", "No")) -> No | N31: =(Table8[[#This Row],[Garage_Out_Date]]-Table8[[#This Row],[Garage_In_Date]]) -> 4.4 | O31: =IF(Table8[[#This Row],[Total_VOR_Days]] >3.5, "Yes", "No") -> Yes | P31: =IF(Table8[[#This Row],[Vehicle_Type]] <> "Specialised", "Not Applicable", IF(AND(Table8[[#This Row],[Hours_To_Book]] <=48, Table8[[#This Row],[Total_VOR_Days]] >3.5), "Ineffective", "Effective")) -> Ineffective | Q31: =IF(OR(Table8[[#This Row],[Garage_In_Date]]="",Table8[[#This Row],[Actual_Repair_Start_Date]]=""),"N/A",(Table8[[#This Row],[Actual_Repair_Start_Date]]-Table8[[#This Row],[Garage_In_Date]])*24) -> 5.75 | R31: =_xlfn.XLOOKUP(Table8[[#This Row],[Vehicle_ID]],Table5[Vehicle_ID],Table5[MOT_Linked],"Not Found") -> Yes
... A101: VH1099 | B101: Standard | C101: Ford Transit | D101: 46096.677 | E101: 46099.56 | F101: 46099.56 | G101: 46105.66 | H101: 46101.458 | I101: 46106 | J101: Unknown / Insufficient Data | K101: Mississippilessly Repairs | L101: =(Table8[[#This Row],[Garage_Booked_DateTime]] - Table8[[#This Row],[Defect_Reported_DateTime]])*24 -> 69.2 | M101: =IF(Table8[[#This Row],[Vehicle_Type]]<>"Specialised", "Not Applicable", IF(Table8[[#This Row],[Hours_To_Book]]>48, "Yes", "No")) -> Not Applicable | N101: =(Table8[[#This Row],[Garage_Out_Date]]-Table8[[#This Row],[Garage_In_Date]]) -> 6.1 | O101: =IF(Table8[[#This Row],[Total_VOR_Days]] >3.5, "Yes", "No") -> Yes | P101: =IF(Table8[[#This Row],[Vehicle_Type]] <> "Specialised", "Not Applicable", IF(AND(Table8[[#This Row],[Hours_To_Book]] <=48, Table8[[#This Row],[Total_VOR_Days]] >3.5), "Ineffective", "Effective")) -> Not Applicable | Q101: =IF(OR(Table8[[#This Row],[Garage_In_Date]]="",Table8[[#This Row],[Actual_Repair_Start_Date]]=""),"N/A",(Table8[[#This Row],[Actual_Repair_Start_Date]]-Table8[[#This Row],[Garage_In_Date]])*24) -> 45.55 | R101: =_xlfn.XLOOKUP(Table8[[#This Row],[Vehicle_ID]],Table5[Vehicle_ID],Table5[MOT_Linked],"Not Found") -> No
J102: =AVERAGEIF(Table8[Primary_Delay_Reason],"Parts on Backorder",Table8[Total_VOR_Days]) -> 6.2

Sheet Data_Cleaning_Log
A1: Issues | B1: Actions Taken
A2: Columns imported as General format | B2: Updated date/time fields to Date/Time, ID fields to Text, numeric fields to Number
A3: Inconsistent garage name spelling | B3: Standardise garage names, e.g Ctrl Perk Repairs changed to Central perk Repairs
A4: 1 Missing Garage_In_Date for Vehicle_ID VH1017 | B4: Excluded from VOR garage turnaround and repair lead time analysis as vehicle arrival date could not be verified
A5: 1 Missing confirmation as to whether VOR days were a result of a defect found during the MOT Test for Vehicle_ID VH1027 | B5: Verified from repair records and MOT history
A6: 2 Missing Repeated_Defect_Last_30_Days value for Vehicle_ID VH1097 and VH1032 | B6: Checked repair history and updated records
A7: 1 Missing Vehicle_Type for Vehicle_ID VH1022 | B7: Verified using Vehicle_ID and updated record

Sheet Summary
B2: Average VOR Days
B4: 4.1
E6: FLEET OPERATIONS AND SLA PERFORMANCE SUMMARY
D9: Metric | E9: Specialised Vehicles | F9: Standard Vehicles
D10: Target SLA | E10: 48 Hours | F10: No strict target
D11: Average hours to book | E11: =AVERAGEIF(Cleaned_Data!B:B,"Specialised",Cleaned_Data!L:L) -> 33.954286 | F11: =AVERAGEIF(Cleaned_Data!B:B,"Standard",Cleaned_Data!L:L) -> 54.247692
D12: Booking SLA Compliance | E12: 0.94 | F12: N/A
D13: Booking SLA Breach Rate | E13: 0.057 | F13: N/A
D14: VOR Targert SLA | E14: 3.5 | F14: 3.5
D15: Average VOR Days | E15: =AVERAGEIF(Cleaned_Data!B:B,"Specialised",Cleaned_Data!N:N) -> 3.9142857 | F15: =AVERAGEIF(Cleaned_Data!B:B,"Standard",Cleaned_Data!N:N) -> 4.4676923
D16: VOR SLA Compliance | E16: =13/35 -> 0.37142857 | F16: =24/65 -> 0.36923077
D17: VOR SLA Breach | E17: =22/35 -> 0.62857143 | F17: =(65-24)/65 -> 0.63076923
D20: Repair Start Delay Analysis
G21: Garage Delay Analysis (Avg Hours to Start Repair) | J21: The Average Miss:
D22: Metric | E22: Value | J22: The Baseline: On average, vehicles are staying in the garage half a day longer (4 days) than the company's goal (3.5 days) by half a day.
D23: Average Hours to Start Repair | E23: =AVERAGEIF(Cleaned_Data!Q2:Q101,"<>N/A",Cleaned_Data!Q2:Q101) -> 14.25202 | G23: Garage Name | H23: Avg Hours to Start
D24: Vehicles with Delayed Start (>0 hours) | E24: =COUNTIF(Cleaned_Data!Q2:Q101,">0") -> 71 | G24: 15 Yemen Rd Garage | H24: =AVERAGEIFS(Cleaned_Data!Q:Q,Cleaned_Data!K:K,"15 Yemen Rd Garage",Cleaned_Data!Q:Q,"<>N/A") -> 15.666667 | J24: The Variation (Standard Deviation of 2):
D25: Vehicles Starting Same Time or Before | E25: =COUNTIF(Cleaned_Data!Q2:Q101,"<=0") -> 28 | G25: Central Perk Repairs | H25: =AVERAGEIFS(Cleaned_Data!Q:Q,Cleaned_Data!K:K,"Central Perk Repairs",Cleaned_Data!Q:Q,"<>N/A") -> 14.576667
D26: Vehicles with N/A Data | E26: =COUNTIF(Cleaned_Data!Q2:Q101,"N/A") -> 1 | G26: Dr Drake Ramoray Autos | H26: =AVERAGEIFS(Cleaned_Data!Q:Q,Cleaned_Data!K:K,"Dr Drake Ramoray Autos",Cleaned_Data!Q:Q,"<>N/A") -> 17.595 | J26: The dataset shows a Standard Deviation of 2 days. Mathematically, this tells us that the majority of vehicle repairs fluctuate wildly between 2 and 6 days( Mean +/- SD).
D27: Total Valid Records | E27: =COUNTIF(Cleaned_Data!Q2:Q101,"<>N/A") -> 99 | G27: Geller Repair Shop | H27: =AVERAGEIFS(Cleaned_Data!Q:Q,Cleaned_Data!K:K,"Geller Repair Shop",Cleaned_Data!Q:Q,"<>N/A") -> 12.127778
D28: % Vehicles with Delayed Start | E28: =IF(E27>0,E24/E27,"N/A") -> 0.71717172 | G28: Joey Special Auto Centre | H28: =AVERAGEIFS(Cleaned_Data!Q:Q,Cleaned_Data!K:K,"Joey Special Auto Centre",Cleaned_Data!Q:Q,"<>N/A") -> 6.3875 | J28: Operational Impact:
D29: Average Delay (Days) | E29: =E23/24 -> 0.59383418 | G29: Miss Chanandler Bong Garage | H29: =AVERAGEIFS(Cleaned_Data!Q:Q,Cleaned_Data!K:K,"Miss Chanandler Bong Garage",Cleaned_Data!Q:Q,"<>N/A") -> 16.291667 | J29: This extreme lack of predictability creates severe planning challenges for the bookings team. Frontline tracking indicates that this variation is heavily driven by
G30: Mississippilessly Repairs | H30: =AVERAGEIFS(Cleaned_Data!Q:Q,Cleaned_Data!K:K,"Mississippilessly Repairs",Cleaned_Data!Q:Q,"<>N/A") -> 11.89
G31: PIVOT Garage Repairs | H31: =AVERAGEIFS(Cleaned_Data!Q:Q,Cleaned_Data!K:K,"PIVOT Garage Repairs",Cleaned_Data!Q:Q,"<>N/A") -> 14.815385
G32: Princess Consuela Auto Centre | H32: =AVERAGEIFS(Cleaned_Data!Q:Q,Cleaned_Data!K:K,"Princess Consuela Auto Centre",Cleaned_Data!Q:Q,"<>N/A") -> 21.038462
G33: Rachel Greep Workshop | H33: =AVERAGEIFS(Cleaned_Data!Q:Q,Cleaned_Data!K:K,"Rachel Greep Workshop",Cleaned_Data!Q:Q,"<>N/A") -> 5.3916667
D36: This analysis measures downtime from Garage_In_Date t0 Garage_Out_Date. It does not capture pre-garage downtime between defect report, booking, recovert, or vehicle arrival. Future analysis would eequiren additional fields such as VOR_Start_Date, Recovery_Booked_Date, and Vehicle_Arrival_Status.

Sheet Dashboard
B2: FLEET MANAGEMENT DASHBOARD
B4: Total Vehicles | D4: Avg VOR Days | F4: VOR SLA Compliance | H4: VOR SLA Breach | J4: Booking SLA Breach | L4: Avg Hours to Book
B5: =COUNTA(Table8[Vehicle_ID]) -> 100 | D5: =ROUND(AVERAGE(Table8[Total_VOR_Days]),1) -> 4.3 | F5: =COUNTIF(Table8[VOR_SLA_Breached?],"No")/COUNTA(Table8[Vehicle_ID]) -> 0.38 | H5: =COUNTIF(Table8[VOR_SLA_Breached?],"Yes")/COUNTA(Table8[Vehicle_ID]) -> 0.62 | J5: =COUNTIF(Table8[Booking_SLA_Breached?],"Yes")/COUNTIF(Table8[Vehicle_Type],"Specialised") -> 0.057142857 | L5: =ROUND(AVERAGE(Table8[Hours_To_Book]),1) -> 47.1
B8: VOR SLA Status | C8: Count | F8: Garage Name | G8: Avg VOR Days
B9: Compliant (≤3.5 days) | C9: =COUNTIF(Table8[VOR_SLA_Breached?],"No") -> 38 | F9: 15 Yemen Rd Garage | G9: =AVERAGEIF(Table8[Garage_Name],"15 Yemen Rd Garage",Table8[Total_VOR_Days]) -> 3.3333333
B10: Breach (>3.5 days) | C10: =COUNTIF(Table8[VOR_SLA_Breached?],"Yes") -> 62 | F10: Central Perk Repairs | G10: =AVERAGEIF(Table8[Garage_Name],"Central Perk Repairs",Table8[Total_VOR_Days]) -> 3.7066667
F11: Dr Drake Ramoray Autos | G11: =AVERAGEIF(Table8[Garage_Name],"Dr Drake Ramoray Autos",Table8[Total_VOR_Days]) -> 4.14
F12: Geller Repair Shop | G12: =AVERAGEIF(Table8[Garage_Name],"Geller Repair Shop",Table8[Total_VOR_Days]) -> 4.2111111
F13: Joey Special Auto Centre | G13: =AVERAGEIF(Table8[Garage_Name],"Joey Special Auto Centre",Table8[Total_VOR_Days]) -> 4.8444444
F14: Miss Chanandler Bong Garage | G14: =AVERAGEIF(Table8[Garage_Name],"Miss Chanandler Bong Garage",Table8[Total_VOR_Days]) -> 3.4833333
F15: Mississippilessly Repairs | G15: =AVERAGEIF(Table8[Garage_Name],"Mississippilessly Repairs",Table8[Total_VOR_Days]) -> 5.79
F16: PIVOT Garage Repairs | G16: =AVERAGEIF(Table8[Garage_Name],"PIVOT Garage Repairs",Table8[Total_VOR_Days]) -> 3.7692308
F17: Princess Consuela Auto Centre | G17: =AVERAGEIF(Table8[Garage_Name],"Princess Consuela Auto Centre",Table8[Total_VOR_Days]) -> 4.9384615
F18: Rachel Greep Workshop | G18: =AVERAGEIF(Table8[Garage_Name],"Rachel Greep Workshop",Table8[Total_VOR_Days]) -> 4.4833333
B26: Delay Reason | C26: Count
B27: None (On Time) | C27: =COUNTIF(Table8[Primary_Delay_Reason],"None (On Time)") -> 38
B28: Parts on Backorder | C28: =COUNTIF(Table8[Primary_Delay_Reason],"Parts on Backorder") -> 15
B29: Garage Capacity / Ramp Delay | C29: =COUNTIF(Table8[Primary_Delay_Reason],"Garage Capacity / Ramp Delay") -> 12
B30: Incorrect Job Scoping | C30: =COUNTIF(Table8[Primary_Delay_Reason],"Incorrect Job Scoping") -> 10
B31: Awaiting Client Authorization | C31: =COUNTIF(Table8[Primary_Delay_Reason],"Awaiting Client Authorization") -> 14
B32: Recovery Delivery Failure | C32: =COUNTIF(Table8[Primary_Delay_Reason],"Recovery Delivery Failure") -> 0
B33: Unknown / Insufficient Data | C33: =COUNTIF(Table8[Primary_Delay_Reason],"Unknown / Insufficient Data") -> 11

Sheet Dashboard_PT
B2: FLEET MANAGEMENT DASHBOARD (PivotTable Version)
B4: VOR SLA Breached? | F4: Avg VOR Days by Garage
B5: Row Labels | C5: Count of Vehicle_ID | F5: Row Labels | G5: Count of Total_VOR_Days
B6: Yes | C6: 7 | F6: Princess Consuela Auto Centre | G6: 7
B7: Grand Total | C7: 7 | F7: Grand Total | G7: 7
B19: Delay Reasons Breakdown | F19: KPI Summary
B20: Row Labels | C20: Count of Vehicle_ID | F20: Count of Vehicle_ID | G20: Average of Total_VOR_Days | H20: Average of Hours_To_Book
B21: Awaiting Client Authorization | C21: 2 | F21: 7 | G21: 6.7571429 | H21: 50.714286
B22: Incorrect Job Scoping | C22: 2
B23: Parts on Backorder | C23: 2
B24: Unknown / Insufficient Data | C24: 1
B25: Grand Total | C25: 7 | G25: VOR by Make / Model
G26: Row Labels | H26: Average of Total_VOR_Days
G27: Ford Transit | H27: 5
G28: Iveco Daily | H28: 7.8
G29: Vauxhall Vivaro | H29: 7.2333333
G30: Grand Total | H30: 6.7571429
